<mujoco model="MuJoCo Model">
  <!--robola compile-->
  <compiler angle="radian"/>

  <option timestep="0.0025" tolerance="1e-10" cone="elliptic" jacobian="dense" iterations="50"/>

  <size nuser_geom="1" nuser_actuator="1"/>

  <visual>
    <headlight ambient="0.4 0.4 0.4"/>
    <map force="0.1" fogstart="1.5" fogend="5"/>
  </visual>

  <default>
    <default class="basketball_base">
      <joint limited="true" armature="0.001" damping="2"/>
      <geom type="mesh" contype="0" conaffinity="0" group="1"/>
      <general ctrllimited="true" ctrlrange="0 1.57" biastype="affine" biasprm="0 -1"/>
      <default class="basketball_viz">
        <geom condim="4"/>
      </default>
      <default class="basketball_col">
        <geom contype="1" conaffinity="1" group="4" solref="0.01" solimp="0.99 0.99 0.01" material="bskt_col"/>
      </default>
    </default>
    <default class="xyz_base">
      <joint limited="true" armature="0.001" damping="2"/>
      <geom type="mesh" contype="0" conaffinity="0" group="1"/>
      <general ctrllimited="true" ctrlrange="0 1.57" biastype="affine" biasprm="0 -1"/>
      <default class="base_viz">
        <geom condim="4" solimp="0.8 0.9 0.01" margin="0.001"/>
      </default>
      <default class="base_col">
        <geom contype="1" conaffinity="1" condim="4" group="4" solimp="0.8 0.9 0.01" margin="0.001" material="xyz_col"/>
      </default>
    </default>
  </default>

  <asset>
    <texture type="skybox" colorspace="auto" builtin="gradient" rgb1="0.5 0.495 0.48" rgb2="0.5 0.495 0.48" width="32" height="192"/>
    <texture type="cube" colorspace="linear" name="T_table" file="../textures/wood2.png"/>
    <texture type="2d" colorspace="linear" name="T_floor" file="../textures/floor2.png"/>
    <texture type="cube" colorspace="linear" name="T_wallmetal" file="../textures/metal.png"/>
    <texture type="cube" colorspace="linear" name="T_bskt" file="../textures/metal1.png"/>
    <material name="basic_floor" texture="T_floor" texrepeat="12 12" shininess="0.3" reflectance="0.2"/>
    <material name="table_wood" texture="T_table" shininess="0.3"/>
    <material name="table_col" specular="0" shininess="0" rgba="0.3 0.3 1 0.5"/>
    <material name="wall_metal" texture="T_wallmetal" shininess="1" reflectance="1"/>
    <material name="bskt_col" specular="0" shininess="0" rgba="0.3 0.3 1 0.5"/>
    <material name="bskt_red" shininess="1" reflectance="0.7" rgba="0.6 0 0 1"/>
    <material name="bskt_orange" shininess="1" reflectance="0.7" rgba="0.7 0.35 0 1"/>
    <material name="bskt_black" shininess="1" reflectance="0.7" rgba="0.15 0.15 0.15 1"/>
    <material name="bskt_white" shininess="1" reflectance="0.7" rgba="0.85 0.85 0.85 1"/>
    <material name="bskt_metal" texture="T_bskt" shininess="1" reflectance="0.7"/>
    <material name="xyz_col" shininess="0" rgba="0.3 0.3 1 0.5"/>
    <mesh name="tablebody" content_type="model/stl" file="../objects/meshes/table/tablebody.stl"/>
    <mesh name="tabletop" content_type="model/stl" file="../objects/meshes/table/tabletop.stl"/>
    <mesh name="backboard" content_type="model/stl" file="../objects/meshes/basketball/backboard.stl"/>
    <mesh name="backboardsquareinner" content_type="model/stl" file="../objects/meshes/basketball/backboardsquareinner.stl"/>
    <mesh name="backboardsquareouter" content_type="model/stl" file="../objects/meshes/basketball/backboardsquareouter.stl"/>
    <mesh name="basketballinner" content_type="model/stl" file="../objects/meshes/basketball/basketballinner.stl"/>
    <mesh name="basketballouter" content_type="model/stl" file="../objects/meshes/basketball/basketballouter.stl"/>
    <mesh name="hoop" content_type="model/stl" file="../objects/meshes/basketball/hoop.stl"/>
    <mesh name="pole" content_type="model/stl" file="../objects/meshes/basketball/pole.stl"/>
    <mesh name="base" content_type="model/stl" file="../objects/meshes/xyz_base/base.stl"/>
    <mesh name="eGripperBase" content_type="model/stl" file="../objects/meshes/xyz_base/eGripperBase.stl"/>
    <mesh name="head" content_type="model/stl" file="../objects/meshes/xyz_base/head.stl"/>
    <mesh name="l0" content_type="model/stl" file="../objects/meshes/xyz_base/l0.stl"/>
    <mesh name="l1" content_type="model/stl" file="../objects/meshes/xyz_base/l1.stl"/>
    <mesh name="l2" content_type="model/stl" file="../objects/meshes/xyz_base/l2.stl"/>
    <mesh name="l3" content_type="model/stl" file="../objects/meshes/xyz_base/l3.stl"/>
    <mesh name="l4" content_type="model/stl" file="../objects/meshes/xyz_base/l4.stl"/>
    <mesh name="l5" content_type="model/stl" file="../objects/meshes/xyz_base/l5.stl"/>
    <mesh name="l6" content_type="model/stl" file="../objects/meshes/xyz_base/l6.stl"/>
    <mesh name="pedestal" content_type="model/stl" file="../objects/meshes/xyz_base/pedestal.stl"/>
  </asset>

  <worldbody>
    <geom name="floor" size="4 4 0.1" pos="0 0 -0.913" type="plane" material="basic_floor"/>
    <camera name="topview" pos="0 0.5 1.5"/>
    <camera name="corner" pos="-1.1 -0.4 0.6" quat="0.305208 -0.230856 -0.557335 0.736838"/>
    <camera name="corner2" pos="1.3 -0.2 1.1" quat="-0.395038 0.262667 -0.434937 0.765363" fovy="60"/>
    <camera name="corner3" pos="0.9 0 1.5" quat="-0.494554 0.105737 -0.255944 0.82385"/>
    <camera name="corner4" pos="0.75 0.075 0.7" quat="-0.395038 0.262667 -0.434937 0.765363" fovy="60"/>
    <light pos="-1 -1 1" dir="0.57735 0.57735 -0.57735" type="directional" castshadow="false" diffuse="0.3 0.3 0.3"/>
    <light pos="1 -1 1" dir="-0.57735 0.57735 -0.57735" type="directional" diffuse="0.3 0.3 0.3"/>
    <light pos="0 1 1" dir="0 -0.707107 -0.707107" type="directional" castshadow="false" diffuse="0.3 0.3 0.3"/>
    <body name="tablelink" pos="0 0.6 0">
      <geom size="0.7 0.4 0.027" pos="0 0 -0.027" type="box" contype="0" conaffinity="0" group="1" material="table_wood"/>
      <geom pos="0 0 -0.65" quat="1 0 0 0" type="mesh" contype="0" conaffinity="0" group="1" material="table_wood" mesh="tablebody"/>
      <geom size="0.7 0.4 0.46" pos="0 0 -0.46" type="box" contype="0" group="4" material="table_col"/>
    </body>
    <body name="RetainingWall" pos="0 0.6 0.06">
      <geom size="0.7 0.01 0.06" pos="0 -0.39 0" type="box" contype="0" material="wall_metal"/>
      <geom size="0.7 0.01 0.06" pos="0 0.39 0" type="box" contype="0" material="wall_metal"/>
      <geom size="0.01 0.38 0.06" pos="-0.69 0 0" type="box" contype="0" material="wall_metal"/>
      <geom size="0.01 0.38 0.06" pos="0.69 0 0" type="box" contype="0" material="wall_metal"/>
    </body>
    <body name="base" childclass="xyz_base">
      <inertial pos="0 0 0" mass="0" diaginertia="0 0 0"/>
      <site name="basesite" pos="0 0 0" size="0.01"/>
      <body name="controller_box">
        <inertial pos="-0.325 0 -0.38" mass="46.64" diaginertia="1.71363 1.27988 0.809981"/>
        <geom size="0.11 0.2 0.265" pos="-0.325 0 -0.38" type="box" rgba="0.2 0.2 0.2 1"/>
      </body>
      <body name="pedestal_feet">
        <inertial pos="-0.1225 0 -0.758" mass="167.09" diaginertia="8.16095 9.59375 15.0785"/>
        <geom size="0.385 0.35 0.155" pos="-0.1225 0 -0.758" type="box" rgba="0.2 0.2 0.2 1"/>
      </body>
      <body name="torso">
        <inertial pos="0 0 0" mass="0.0001" diaginertia="1e-08 1e-08 1e-08"/>
        <geom size="0.05 0.05 0.05" type="box" rgba="0.2 0.2 0.2 1"/>
      </body>
      <body name="pedestal">
        <inertial pos="0 0 0" quat="0.659267 -0.259505 -0.260945 0.655692" mass="60.864" diaginertia="6.0869 5.81635 4.20915"/>
        <geom pos="0.26 0.345 -0.91488" quat="0.5 0.5 -0.5 -0.5" rgba="0.2 0.2 0.2 1" mesh="pedestal"/>
        <geom size="0.18 0.31" pos="-0.02 0 -0.29" type="cylinder" rgba="0.2 0.2 0.2 0"/>
      </body>
      <body name="right_arm_base_link">
        <inertial pos="-0.0006241 -2.8025e-05 0.065404" quat="-0.209285 0.674441 0.227335 0.670558" mass="2.0687" diaginertia="0.00740351 0.00681776 0.00672942"/>
        <geom rgba="0.5 0.1 0.1 1" mesh="base"/>
        <geom size="0.08 0.12" pos="0 0 0.12" type="cylinder" rgba="0.5 0.1 0.1 0"/>
        <body name="right_l0" pos="0 0 0.08">
          <inertial pos="0.024366 0.010969 0.14363" quat="0.894823 0.00899958 -0.170275 0.412573" mass="5.3213" diaginertia="0.0651588 0.0510944 0.0186218"/>
          <joint name="right_j0" pos="0 0 0" axis="0 0 1" range="-3.0503 3.0503" damping="10"/>
          <geom rgba="0.5 0.1 0.1 1" mesh="l0"/>
          <body name="head" pos="0 0 0.2965">
            <inertial pos="0.0053207 -2.6549e-05 0.1021" quat="0.999993 7.08405e-05 -0.00359857 -0.000626247" mass="1.5795" diaginertia="0.0118334 0.00827089 0.00496574"/>
            <geom rgba="0.5 0.1 0.1 1" mesh="head"/>
            <body name="screen" pos="0.03 0 0.105" quat="0.5 0.5 0.5 0.5">
              <inertial pos="0 0 0" mass="0.0001" diaginertia="1e-08 1e-08 1e-08"/>
              <geom size="0.12 0.07 0.001" type="box" rgba="0.2 0.2 0.2 0"/>
            </body>
            <body name="head_camera" pos="0.0228027 0 0.216572" quat="0.342813 -0.618449 0.618449 -0.342813">
              <inertial pos="0.0228027 0 0.216572" quat="0.342813 -0.618449 0.618449 -0.342813" mass="0" diaginertia="0 0 0"/>
              <site name="headsite" pos="0 0 0" size="0.01"/>
            </body>
          </body>
          <body name="right_torso_itb" pos="-0.055 0 0.22" quat="0.707107 0 -0.707107 0">
            <inertial pos="0 0 0" mass="0.0001" diaginertia="1e-08 1e-08 1e-08"/>
          </body>
          <body name="right_l1" pos="0.081 0.05 0.237" quat="0.5 -0.5 0.5 0.5">
            <inertial pos="-0.0030849 -0.026811 0.092521" quat="0.424888 0.891987 0.132364 -0.0794296" mass="4.505" diaginertia="0.0224339 0.0221624 0.0097097"/>
            <joint name="right_j1" pos="0 0 0" axis="0 0 1" range="-3.8 -0.5" damping="10"/>
            <geom rgba="0.5 0.1 0.1 1" mesh="l1"/>
            <body name="right_l2" pos="0 -0.14 0.1425" quat="0.707107 0.707107 0 0">
              <inertial pos="-0.00016044 -0.014967 0.13582" quat="0.707831 -0.0524761 0.0516007 0.702537" mass="1.745" diaginertia="0.0257928 0.025506 0.00292515"/>
              <joint name="right_j2" pos="0 0 0" axis="0 0 1" range="-3.0426 3.0426" damping="10"/>
              <geom rgba="0.5 0.1 0.1 1" mesh="l2"/>
              <geom size="0.06 0.17" pos="0 0 0.08" type="cylinder" rgba="0.5 0.1 0.1 0"/>
              <body name="right_l3" pos="0 -0.042 0.26" quat="0.707107 -0.707107 0 0">
                <inertial pos="-0.0048135 -0.0281 -0.084154" quat="0.902999 0.385391 -0.0880901 0.168247" mass="2.5097" diaginertia="0.0102404 0.0096997 0.00369622"/>
                <joint name="right_j3" pos="0 0 0" axis="0 0 1" range="-3.0439 3.0439" damping="10"/>
                <geom rgba="0.5 0.1 0.1 1" mesh="l3"/>
                <site name="armsite" pos="0 0 0" size="0.01"/>
                <body name="right_l4" pos="0 -0.125 -0.1265" quat="0.707107 0.707107 0 0">
                  <inertial pos="-0.0018844 0.0069001 0.1341" quat="0.803612 0.031257 -0.0298334 0.593582" mass="1.1136" diaginertia="0.0136549 0.0135493 0.00127353"/>
                  <joint name="right_j4" pos="0 0 0" axis="0 0 1" range="-2.9761 2.9761" damping="10"/>
                  <geom rgba="0.5 0.1 0.1 1" mesh="l4"/>
                  <geom size="0.045 0.15" pos="0 0 0.11" type="cylinder" rgba="0.5 0.1 0.1 0"/>
                  <body name="right_arm_itb" pos="-0.055 0 0.075" quat="0.707107 0 -0.707107 0">
                    <inertial pos="0 0 0" mass="0.0001" diaginertia="1e-08 1e-08 1e-08"/>
                  </body>
                  <body name="right_l5" pos="0 0.031 0.275" quat="0.707107 -0.707107 0 0">
                    <inertial pos="0.0061133 -0.023697 0.076416" quat="0.404076 0.9135 0.0473125 0.00158335" mass="1.5625" diaginertia="0.00474131 0.00422857 0.00190672"/>
                    <joint name="right_j5" pos="0 0 0" axis="0 0 1" range="-2.9761 2.9761" damping="10"/>
                    <geom rgba="0.5 0.1 0.1 1" mesh="l5"/>
                    <body name="right_hand_camera" pos="0.039552 -0.033 0.0695" quat="0.707107 0 0.707107 0">
                      <inertial pos="0.039552 -0.033 0.0695" quat="0.707107 0 0.707107 0" mass="0" diaginertia="0 0 0"/>
                    </body>
                    <body name="right_wrist" pos="0 0 0.10541" quat="0.707107 0.707107 0 0">
                      <inertial pos="0 0 0.10541" quat="0.707107 0.707107 0 0" mass="0" diaginertia="0 0 0"/>
                    </body>
                    <body name="right_l6" pos="0 -0.11 0.1053" quat="0.0616248 0.06163 -0.704416 0.704416">
                      <inertial pos="-8.0726e-06 0.0085838 -0.0049566" quat="0.479044 0.515636 -0.513069 0.491322" mass="0.3292" diaginertia="0.000360258 0.000311068 0.000214974"/>
                      <joint name="right_j6" pos="0 0 0" axis="0 0 1" range="-4.7124 4.7124" damping="10"/>
                      <geom contype="4" conaffinity="2" rgba="0.5 0.1 0.1 1" mesh="l6"/>
                      <geom size="0.055 0.025" pos="0 0.015 -0.01" type="cylinder" rgba="0.5 0.1 0.1 0"/>
                      <body name="right_hand" pos="0 0 0.0245" quat="0.707107 0 0 0.707107">
                        <inertial pos="1e-08 1e-08 1e-08" quat="0.820473 0.339851 -0.17592 0.424708" mass="1e-08" diaginertia="1e-08 1e-08 1e-08"/>
                        <geom pos="0 0 0.03" quat="1 0 0 0" contype="1" conaffinity="1" rgba="0.5 0.1 0.1 1" mesh="eGripperBase"/>
                        <geom size="0.035 0.014" pos="0 0 0.015" type="cylinder" rgba="0 0 0 1"/>
                        <body name="hand" pos="0 0 0.12" quat="-0.707107 0 0.707107 0">
                          <geom name="rail" size="0.005 0.055 0.005" pos="-0.05 0 0" type="box" friction="2 0.1 0.002" density="7850"/>
                          <site name="endEffector" pos="0.04 0 0" size="0.01" rgba="1 1 1 0"/>
                          <camera name="behindGripper" pos="0 0 -0.5" quat="0 1 0 0" mode="track" fovy="60"/>
                          <camera name="gripperPOV" pos="0.04 -0.06 0" quat="-0.609711 -0.792624 0 0" mode="track" fovy="90"/>
                          <camera name="gripper_depth_cam" pos="0.05 0 0" quat="0.707107 0 0.707107 0" mode="track" fovy="75"/>
                          <body name="rightclaw" pos="0 -0.05 0">
                            <joint name="r_close" pos="0 0 0" axis="0 1 0" type="slide" range="0 0.04" armature="100" damping="1000"/>
                            <geom name="rightclaw_it" class="base_col" size="0.045 0.003 0.015" type="box" rgba="1 1 1 1"/>
                            <site name="rightEndEffector" pos="0.045 0 0" size="0.01" rgba="1 0 0 1"/>
                            <body name="rightpad" pos="0 0.003 0">
                              <geom name="rightpad_geom" size="0.045 0.003 0.015" type="box" contype="1" conaffinity="1" condim="4" friction="2 0.1 0.002" solref="0.01" solimp="0.95 0.99 0.01" margin="0.001" mass="0" rgba="1 1 1 1"/>
                            </body>
                          </body>
                          <body name="leftclaw" pos="0 0.05 0">
                            <joint name="l_close" pos="0 0 0" axis="0 1 0" type="slide" range="-0.03 0" armature="100" damping="1000"/>
                            <geom name="leftclaw_it" class="base_col" size="0.045 0.003 0.015" type="box" rgba="0 1 1 1"/>
                            <site name="leftEndEffector" pos="0.045 0 0" size="0.01" rgba="1 0 0 1"/>
                            <body name="leftpad" pos="0 -0.003 0">
                              <geom name="leftpad_geom" size="0.045 0.003 0.015" type="box" contype="1" conaffinity="1" condim="4" friction="2 0.1 0.002" solref="0.01" solimp="0.95 0.99 0.01" margin="0.001" rgba="0 1 1 1"/>
                            </body>
                          </body>
                        </body>
                      </body>
                    </body>
                  </body>
                  <body name="right_l4_2">
                    <inertial pos="1e-08 1e-08 1e-08" quat="0.820473 0.339851 -0.17592 0.424708" mass="1e-08" diaginertia="1e-08 1e-08 1e-08"/>
                  </body>
                </body>
              </body>
              <body name="right_l2_2">
                <inertial pos="1e-08 1e-08 1e-08" quat="0.820473 0.339851 -0.17592 0.424708" mass="1e-08" diaginertia="1e-08 1e-08 1e-08"/>
              </body>
            </body>
            <body name="right_l1_2">
              <inertial pos="1e-08 1e-08 1e-08" quat="0.820473 0.339851 -0.17592 0.424708" mass="1e-08" diaginertia="1e-08 1e-08 1e-08"/>
              <geom size="0.07 0.07" pos="0 0 0.035" type="cylinder" rgba="0.2 0.2 0.2 0"/>
            </body>
          </body>
        </body>
      </body>
    </body>
    <body name="mocap" mocap="true">
      <geom size="0.01" contype="0" conaffinity="0" rgba="0 0.5 0.5 0"/>
      <site name="mocap" pos="0 0 0" size="0.01" rgba="0 0.5 0.5 0"/>
    </body>
    <body name="bsktball" pos="0 0.6 0.03">
      <joint type="free"/>
      <body name="basketball" childclass="basketball_base">
        <geom material="bskt_black" mesh="basketballinner"/>
        <geom material="bskt_orange" mesh="basketballouter"/>
        <geom name="objGeom" class="basketball_col" size="0.03" type="sphere" mass="0.1"/>
      </body>
    </body>
    <body name="basket_goal" pos="0 0.9 0">
      <body name="basketballhoop" childclass="basketball_base">
        <body name="backboardlink">
          <geom pos="0 0 0.29" quat="1 0 0 0" material="bskt_white" mesh="backboard"/>
          <geom pos="0 -0.002 0.29" quat="1 0 0 0" material="bskt_white" mesh="backboardsquareinner"/>
          <geom pos="0 -0.001 0.29" quat="1 0 0 0" material="bskt_red" mesh="backboardsquareouter"/>
          <geom material="bskt_metal" mesh="pole"/>
          <geom class="basketball_col" size="0.1 0.01 0.07" pos="0 0 0.29" type="box" mass="0.2"/>
          <geom class="basketball_col" size="0.007 0.108" pos="0 0 0.118" type="cylinder" mass="0.2"/>
          <geom class="basketball_col" size="0.013 0.005" pos="0 0 0.005" type="cylinder" mass="0.01"/>
          <body name="hooplink" pos="0 -0.083 0.25">
            <geom pos="0 0 -0.001" quat="1 0 0 0" material="bskt_red" mesh="hoop"/>
            <geom class="basketball_col" size="0.01 0.014 0.004" pos="0 0.06 0" type="box"/>
            <geom class="basketball_col" size="0.01 0.016" pos="0.031 0.032 -0.001" quat="0.653269 0.653402 0.27044 0.270496" type="capsule"/>
            <geom class="basketball_col" size="0.01 0.016" pos="0 0.045 -0.001" quat="0.707388 0 0.706825 0" type="capsule"/>
            <geom class="basketball_col" size="0.01 0.016" pos="0.044 0 -0.001" quat="0.707388 0.706825 0 0" type="capsule"/>
            <geom class="basketball_col" size="0.01 0.016" pos="-0.044 0 -0.001" quat="0.707388 0.706825 0 0" type="capsule"/>
            <geom class="basketball_col" size="0.01 0.016" pos="0 -0.045 -0.001" quat="0.707388 0 0.706825 0" type="capsule"/>
            <geom class="basketball_col" size="0.01 0.016" pos="-0.031 0.032 -0.001" quat="0.653595 0.653075 -0.270576 -0.27036" type="capsule"/>
            <geom class="basketball_col" size="0.01 0.016" pos="-0.031 -0.032 -0.001" quat="0.653595 0.653075 0.270576 0.27036" type="capsule"/>
            <geom class="basketball_col" size="0.01 0.016" pos="0.031 -0.032 -0.001" quat="0.653595 0.653075 -0.270576 -0.27036" type="capsule"/>
            <site name="goal" pos="0 0 0" size="0.01" rgba="1 0 0 1"/>
          </body>
        </body>
      </body>
    </body>
  </worldbody>

  <equality>
    <weld body1="mocap" body2="hand" anchor="0 0 0" relpose="0 0 0 0 0 0 0" torquescale="1"/>
  </equality>

  <actuator>
    <general joint="r_close" ctrllimited="true" ctrlrange="-1 1" biastype="affine" gainprm="400" biasprm="0 -400" user="1"/>
    <general joint="l_close" ctrllimited="true" ctrlrange="-1 1" biastype="affine" gainprm="400" biasprm="0 -400" user="1"/>
  </actuator>
</mujoco>
